[2024-03-18T04:45:36.378+0000] {taskinstance.py:1979} INFO - Dependencies all met for dep_context=non-requeueable deps ti=<TaskInstance: sftp_sync.sync_files_task manual__2024-03-18T04:45:29.744195+00:00 [queued]>
[2024-03-18T04:45:36.396+0000] {taskinstance.py:1979} INFO - Dependencies all met for dep_context=requeueable deps ti=<TaskInstance: sftp_sync.sync_files_task manual__2024-03-18T04:45:29.744195+00:00 [queued]>
[2024-03-18T04:45:36.396+0000] {taskinstance.py:2193} INFO - Starting attempt 1 of 2
[2024-03-18T04:45:36.424+0000] {taskinstance.py:2217} INFO - Executing <Task(PythonOperator): sync_files_task> on 2024-03-18 04:45:29.744195+00:00
[2024-03-18T04:45:36.449+0000] {standard_task_runner.py:60} INFO - Started process 605 to run task
[2024-03-18T04:45:36.455+0000] {standard_task_runner.py:87} INFO - Running: ['***', 'tasks', 'run', 'sftp_sync', 'sync_files_task', 'manual__2024-03-18T04:45:29.744195+00:00', '--job-id', '45', '--raw', '--subdir', 'DAGS_FOLDER/sftp_sync_between_source_and_target.py', '--cfg-path', '/tmp/tmpw4f950zf']
[2024-03-18T04:45:36.463+0000] {standard_task_runner.py:88} INFO - Job 45: Subtask sync_files_task
[2024-03-18T04:45:36.650+0000] {task_command.py:423} INFO - Running <TaskInstance: sftp_sync.sync_files_task manual__2024-03-18T04:45:29.744195+00:00 [running]> on host 78c95bc5c908
[2024-03-18T04:45:36.796+0000] {taskinstance.py:2513} INFO - Exporting env vars: AIRFLOW_CTX_DAG_OWNER='***' AIRFLOW_CTX_DAG_ID='sftp_sync' AIRFLOW_CTX_TASK_ID='sync_files_task' AIRFLOW_CTX_EXECUTION_DATE='2024-03-18T04:45:29.744195+00:00' AIRFLOW_CTX_TRY_NUMBER='1' AIRFLOW_CTX_DAG_RUN_ID='manual__2024-03-18T04:45:29.744195+00:00'
[2024-03-18T04:45:36.800+0000] {ssh.py:301} WARNING - No Host Key Verification. This won't protect against Man-In-The-Middle attacks
[2024-03-18T04:45:36.832+0000] {transport.py:1909} INFO - Connected (version 2.0, client OpenSSH_8.9p1)
[2024-03-18T04:45:37.063+0000] {transport.py:1909} INFO - Authentication (password) successful!
[2024-03-18T04:45:37.149+0000] {sftp.py:169} INFO - [chan 0] Opened sftp connection (server version 3)
[2024-03-18T04:45:37.157+0000] {ssh.py:301} WARNING - No Host Key Verification. This won't protect against Man-In-The-Middle attacks
[2024-03-18T04:45:37.171+0000] {ssh.py:343} INFO - Failed to connect. Sleeping before retry attempt 1
[2024-03-18T04:45:41.750+0000] {ssh.py:343} INFO - Failed to connect. Sleeping before retry attempt 2
[2024-03-18T04:45:46.742+0000] {taskinstance.py:2731} ERROR - Task failed with exception
Traceback (most recent call last):
  File "/home/airflow/.local/lib/python3.8/site-packages/airflow/models/taskinstance.py", line 444, in _execute_task
    result = _execute_callable(context=context, **execute_callable_kwargs)
  File "/home/airflow/.local/lib/python3.8/site-packages/airflow/models/taskinstance.py", line 414, in _execute_callable
    return execute_callable(context=context, **execute_callable_kwargs)
  File "/home/airflow/.local/lib/python3.8/site-packages/airflow/operators/python.py", line 200, in execute
    return_value = self.execute_callable()
  File "/home/airflow/.local/lib/python3.8/site-packages/airflow/operators/python.py", line 217, in execute_callable
    return self.python_callable(*self.op_args, **self.op_kwargs)
  File "/opt/airflow/dags/sftp_sync_between_source_and_target.py", line 16, in sync_files
    dest_files = dest_hook.list_directory('/home/airflow/filesystem/')
  File "/home/airflow/.local/lib/python3.8/site-packages/airflow/providers/sftp/hooks/sftp.py", line 160, in list_directory
    conn = self.get_conn()
  File "/home/airflow/.local/lib/python3.8/site-packages/airflow/providers/sftp/hooks/sftp.py", line 126, in get_conn
    self.conn = super().get_conn().open_sftp()
  File "/home/airflow/.local/lib/python3.8/site-packages/airflow/providers/ssh/hooks/ssh.py", line 347, in get_conn
    for attempt in Retrying(
  File "/home/airflow/.local/lib/python3.8/site-packages/tenacity/__init__.py", line 347, in __iter__
    do = self.iter(retry_state=retry_state)
  File "/home/airflow/.local/lib/python3.8/site-packages/tenacity/__init__.py", line 325, in iter
    raise retry_exc.reraise()
  File "/home/airflow/.local/lib/python3.8/site-packages/tenacity/__init__.py", line 158, in reraise
    raise self.last_attempt.result()
  File "/usr/local/lib/python3.8/concurrent/futures/_base.py", line 437, in result
    return self.__get_result()
  File "/usr/local/lib/python3.8/concurrent/futures/_base.py", line 389, in __get_result
    raise self._exception
  File "/home/airflow/.local/lib/python3.8/site-packages/airflow/providers/ssh/hooks/ssh.py", line 354, in get_conn
    client.connect(**connect_kwargs)
  File "/home/airflow/.local/lib/python3.8/site-packages/paramiko/client.py", line 409, in connect
    raise NoValidConnectionsError(errors)
paramiko.ssh_exception.NoValidConnectionsError: [Errno None] Unable to connect to port 22 on 192.168.48.10
[2024-03-18T04:45:46.840+0000] {taskinstance.py:1149} INFO - Marking task as UP_FOR_RETRY. dag_id=sftp_sync, task_id=sync_files_task, execution_date=20240318T044529, start_date=20240318T044536, end_date=20240318T044546
[2024-03-18T04:45:46.897+0000] {standard_task_runner.py:107} ERROR - Failed to execute job 45 for task sync_files_task ([Errno None] Unable to connect to port 22 on 192.168.48.10; 605)
[2024-03-18T04:45:46.926+0000] {local_task_job_runner.py:234} INFO - Task exited with return code 1
[2024-03-18T04:45:46.981+0000] {taskinstance.py:3312} INFO - 0 downstream tasks scheduled from follow-on schedule check
