[2024-03-18T05:20:08.547+0000] {taskinstance.py:1979} INFO - Dependencies all met for dep_context=non-requeueable deps ti=<TaskInstance: sftp_sync.sync_files_task manual__2024-03-18T05:20:01.280827+00:00 [queued]>
[2024-03-18T05:20:08.565+0000] {taskinstance.py:1979} INFO - Dependencies all met for dep_context=requeueable deps ti=<TaskInstance: sftp_sync.sync_files_task manual__2024-03-18T05:20:01.280827+00:00 [queued]>
[2024-03-18T05:20:08.566+0000] {taskinstance.py:2193} INFO - Starting attempt 1 of 2
[2024-03-18T05:20:08.593+0000] {taskinstance.py:2217} INFO - Executing <Task(PythonOperator): sync_files_task> on 2024-03-18 05:20:01.280827+00:00
[2024-03-18T05:20:08.620+0000] {standard_task_runner.py:60} INFO - Started process 1213 to run task
[2024-03-18T05:20:08.629+0000] {standard_task_runner.py:87} INFO - Running: ['***', 'tasks', 'run', 'sftp_sync', 'sync_files_task', 'manual__2024-03-18T05:20:01.280827+00:00', '--job-id', '60', '--raw', '--subdir', 'DAGS_FOLDER/sftp_sync_between_source_and_target.py', '--cfg-path', '/tmp/tmpa88cefks']
[2024-03-18T05:20:08.631+0000] {standard_task_runner.py:88} INFO - Job 60: Subtask sync_files_task
[2024-03-18T05:20:08.720+0000] {task_command.py:423} INFO - Running <TaskInstance: sftp_sync.sync_files_task manual__2024-03-18T05:20:01.280827+00:00 [running]> on host 78c95bc5c908
[2024-03-18T05:20:08.817+0000] {taskinstance.py:2513} INFO - Exporting env vars: AIRFLOW_CTX_DAG_OWNER='***' AIRFLOW_CTX_DAG_ID='sftp_sync' AIRFLOW_CTX_TASK_ID='sync_files_task' AIRFLOW_CTX_EXECUTION_DATE='2024-03-18T05:20:01.280827+00:00' AIRFLOW_CTX_TRY_NUMBER='1' AIRFLOW_CTX_DAG_RUN_ID='manual__2024-03-18T05:20:01.280827+00:00'
[2024-03-18T05:20:08.827+0000] {ssh.py:301} WARNING - No Host Key Verification. This won't protect against Man-In-The-Middle attacks
[2024-03-18T05:20:08.849+0000] {transport.py:1909} INFO - Connected (version 2.0, client OpenSSH_8.9p1)
[2024-03-18T05:20:09.090+0000] {transport.py:1909} INFO - Authentication (password) successful!
[2024-03-18T05:20:09.171+0000] {sftp.py:169} INFO - [chan 0] Opened sftp connection (server version 3)
[2024-03-18T05:20:09.180+0000] {ssh.py:301} WARNING - No Host Key Verification. This won't protect against Man-In-The-Middle attacks
[2024-03-18T05:20:09.218+0000] {transport.py:1909} INFO - Connected (version 2.0, client OpenSSH_8.9p1)
[2024-03-18T05:20:09.339+0000] {transport.py:1909} INFO - Authentication (password) successful!
[2024-03-18T05:20:09.436+0000] {sftp.py:169} INFO - [chan 0] Opened sftp connection (server version 3)
[2024-03-18T05:20:09.441+0000] {logging_mixin.py:188} INFO - Transforming files...
[2024-03-18T05:20:09.443+0000] {taskinstance.py:2731} ERROR - Task failed with exception
Traceback (most recent call last):
  File "/home/airflow/.local/lib/python3.8/site-packages/airflow/models/taskinstance.py", line 444, in _execute_task
    result = _execute_callable(context=context, **execute_callable_kwargs)
  File "/home/airflow/.local/lib/python3.8/site-packages/airflow/models/taskinstance.py", line 414, in _execute_callable
    return execute_callable(context=context, **execute_callable_kwargs)
  File "/home/airflow/.local/lib/python3.8/site-packages/airflow/operators/python.py", line 200, in execute
    return_value = self.execute_callable()
  File "/home/airflow/.local/lib/python3.8/site-packages/airflow/operators/python.py", line 217, in execute_callable
    return self.python_callable(*self.op_args, **self.op_kwargs)
  File "/opt/airflow/dags/sftp_sync_between_source_and_target.py", line 30, in sync_files
    dest_hook.store_file(
  File "/home/airflow/.local/lib/python3.8/site-packages/airflow/providers/sftp/hooks/sftp.py", line 256, in store_file
    conn.put(local_full_path, remote_full_path, confirm=confirm)
  File "/home/airflow/.local/lib/python3.8/site-packages/paramiko/sftp_client.py", line 759, in put
    return self.putfo(fl, remotepath, file_size, callback, confirm)
  File "/home/airflow/.local/lib/python3.8/site-packages/paramiko/sftp_client.py", line 714, in putfo
    with self.file(remotepath, "wb") as fr:
  File "/home/airflow/.local/lib/python3.8/site-packages/paramiko/sftp_client.py", line 372, in open
    t, msg = self._request(CMD_OPEN, filename, imode, attrblock)
  File "/home/airflow/.local/lib/python3.8/site-packages/paramiko/sftp_client.py", line 857, in _request
    return self._read_response(num)
  File "/home/airflow/.local/lib/python3.8/site-packages/paramiko/sftp_client.py", line 909, in _read_response
    self._convert_status(msg)
  File "/home/airflow/.local/lib/python3.8/site-packages/paramiko/sftp_client.py", line 940, in _convert_status
    raise IOError(errno.EACCES, text)
PermissionError: [Errno 13] Permission denied
[2024-03-18T05:20:09.510+0000] {taskinstance.py:1149} INFO - Marking task as UP_FOR_RETRY. dag_id=sftp_sync, task_id=sync_files_task, execution_date=20240318T052001, start_date=20240318T052008, end_date=20240318T052009
[2024-03-18T05:20:09.541+0000] {standard_task_runner.py:107} ERROR - Failed to execute job 60 for task sync_files_task ([Errno 13] Permission denied; 1213)
[2024-03-18T05:20:09.619+0000] {local_task_job_runner.py:234} INFO - Task exited with return code 1
[2024-03-18T05:20:09.716+0000] {taskinstance.py:3312} INFO - 0 downstream tasks scheduled from follow-on schedule check
