[2024-03-18T07:54:18.504+0000] {taskinstance.py:1979} INFO - Dependencies all met for dep_context=non-requeueable deps ti=<TaskInstance: sftp_sync.sync_files_task manual__2024-03-18T07:54:10.213408+00:00 [queued]>
[2024-03-18T07:54:18.527+0000] {taskinstance.py:1979} INFO - Dependencies all met for dep_context=requeueable deps ti=<TaskInstance: sftp_sync.sync_files_task manual__2024-03-18T07:54:10.213408+00:00 [queued]>
[2024-03-18T07:54:18.528+0000] {taskinstance.py:2193} INFO - Starting attempt 1 of 2
[2024-03-18T07:54:18.561+0000] {taskinstance.py:2217} INFO - Executing <Task(PythonOperator): sync_files_task> on 2024-03-18 07:54:10.213408+00:00
[2024-03-18T07:54:18.582+0000] {standard_task_runner.py:60} INFO - Started process 1173 to run task
[2024-03-18T07:54:18.611+0000] {standard_task_runner.py:87} INFO - Running: ['***', 'tasks', 'run', 'sftp_sync', 'sync_files_task', 'manual__2024-03-18T07:54:10.213408+00:00', '--job-id', '74', '--raw', '--subdir', 'DAGS_FOLDER/sftp_sync_between_source_and_target.py', '--cfg-path', '/tmp/tmpkgyo38tb']
[2024-03-18T07:54:18.623+0000] {standard_task_runner.py:88} INFO - Job 74: Subtask sync_files_task
[2024-03-18T07:54:18.965+0000] {task_command.py:423} INFO - Running <TaskInstance: sftp_sync.sync_files_task manual__2024-03-18T07:54:10.213408+00:00 [running]> on host fa05d1b87173
[2024-03-18T07:54:19.235+0000] {taskinstance.py:2513} INFO - Exporting env vars: AIRFLOW_CTX_DAG_OWNER='***' AIRFLOW_CTX_DAG_ID='sftp_sync' AIRFLOW_CTX_TASK_ID='sync_files_task' AIRFLOW_CTX_EXECUTION_DATE='2024-03-18T07:54:10.213408+00:00' AIRFLOW_CTX_TRY_NUMBER='1' AIRFLOW_CTX_DAG_RUN_ID='manual__2024-03-18T07:54:10.213408+00:00'
[2024-03-18T07:54:19.257+0000] {ssh.py:301} WARNING - No Host Key Verification. This won't protect against Man-In-The-Middle attacks
[2024-03-18T07:54:19.337+0000] {transport.py:1909} INFO - Connected (version 2.0, client OpenSSH_8.9p1)
[2024-03-18T07:54:20.002+0000] {transport.py:1909} INFO - Authentication (password) successful!
[2024-03-18T07:54:20.166+0000] {sftp.py:169} INFO - [chan 0] Opened sftp connection (server version 3)
[2024-03-18T07:54:20.181+0000] {ssh.py:301} WARNING - No Host Key Verification. This won't protect against Man-In-The-Middle attacks
[2024-03-18T07:54:20.244+0000] {transport.py:1909} INFO - Connected (version 2.0, client OpenSSH_8.9p1)
[2024-03-18T07:54:20.584+0000] {transport.py:1909} INFO - Authentication (password) successful!
[2024-03-18T07:54:20.714+0000] {sftp.py:169} INFO - [chan 0] Opened sftp connection (server version 3)
[2024-03-18T07:54:20.719+0000] {logging_mixin.py:188} INFO - ['file1.txt']
[2024-03-18T07:54:20.725+0000] {logging_mixin.py:188} INFO - Transforming files...
[2024-03-18T07:54:20.744+0000] {taskinstance.py:2731} ERROR - Task failed with exception
Traceback (most recent call last):
  File "/home/airflow/.local/lib/python3.8/site-packages/airflow/models/taskinstance.py", line 444, in _execute_task
    result = _execute_callable(context=context, **execute_callable_kwargs)
  File "/home/airflow/.local/lib/python3.8/site-packages/airflow/models/taskinstance.py", line 414, in _execute_callable
    return execute_callable(context=context, **execute_callable_kwargs)
  File "/home/airflow/.local/lib/python3.8/site-packages/airflow/operators/python.py", line 200, in execute
    return_value = self.execute_callable()
  File "/home/airflow/.local/lib/python3.8/site-packages/airflow/operators/python.py", line 217, in execute_callable
    return self.python_callable(*self.op_args, **self.op_kwargs)
  File "/opt/airflow/dags/sftp_sync_between_source_and_target.py", line 25, in sync_files
    dest_hook.store_file(f'/tmp/{file}', f'/{file}')
  File "/home/airflow/.local/lib/python3.8/site-packages/airflow/providers/sftp/hooks/sftp.py", line 256, in store_file
    conn.put(local_full_path, remote_full_path, confirm=confirm)
  File "/home/airflow/.local/lib/python3.8/site-packages/paramiko/sftp_client.py", line 757, in put
    file_size = os.stat(localpath).st_size
FileNotFoundError: [Errno 2] No such file or directory: '/file1.txt'
[2024-03-18T07:54:20.850+0000] {taskinstance.py:1149} INFO - Marking task as UP_FOR_RETRY. dag_id=sftp_sync, task_id=sync_files_task, execution_date=20240318T075410, start_date=20240318T075418, end_date=20240318T075420
[2024-03-18T07:54:21.010+0000] {standard_task_runner.py:107} ERROR - Failed to execute job 74 for task sync_files_task ([Errno 2] No such file or directory: '/file1.txt'; 1173)
[2024-03-18T07:54:21.184+0000] {local_task_job_runner.py:234} INFO - Task exited with return code 1
[2024-03-18T07:54:21.390+0000] {taskinstance.py:3312} INFO - 0 downstream tasks scheduled from follow-on schedule check
