[2024-03-18T07:55:15.814+0000] {taskinstance.py:1979} INFO - Dependencies all met for dep_context=non-requeueable deps ti=<TaskInstance: sftp_sync.sync_files_task manual__2024-03-18T07:54:10.213408+00:00 [queued]>
[2024-03-18T07:55:15.823+0000] {taskinstance.py:1979} INFO - Dependencies all met for dep_context=requeueable deps ti=<TaskInstance: sftp_sync.sync_files_task manual__2024-03-18T07:54:10.213408+00:00 [queued]>
[2024-03-18T07:55:15.823+0000] {taskinstance.py:2193} INFO - Starting attempt 2 of 3
[2024-03-18T07:55:15.842+0000] {taskinstance.py:2217} INFO - Executing <Task(PythonOperator): sync_files_task> on 2024-03-18 07:54:10.213408+00:00
[2024-03-18T07:55:15.854+0000] {standard_task_runner.py:60} INFO - Started process 1201 to run task
[2024-03-18T07:55:15.861+0000] {standard_task_runner.py:87} INFO - Running: ['***', 'tasks', 'run', 'sftp_sync', 'sync_files_task', 'manual__2024-03-18T07:54:10.213408+00:00', '--job-id', '76', '--raw', '--subdir', 'DAGS_FOLDER/sftp_sync_between_source_and_target.py', '--cfg-path', '/tmp/tmp8nh7a6r9']
[2024-03-18T07:55:15.864+0000] {standard_task_runner.py:88} INFO - Job 76: Subtask sync_files_task
[2024-03-18T07:55:15.928+0000] {task_command.py:423} INFO - Running <TaskInstance: sftp_sync.sync_files_task manual__2024-03-18T07:54:10.213408+00:00 [running]> on host fa05d1b87173
[2024-03-18T07:55:16.016+0000] {taskinstance.py:2513} INFO - Exporting env vars: AIRFLOW_CTX_DAG_OWNER='***' AIRFLOW_CTX_DAG_ID='sftp_sync' AIRFLOW_CTX_TASK_ID='sync_files_task' AIRFLOW_CTX_EXECUTION_DATE='2024-03-18T07:54:10.213408+00:00' AIRFLOW_CTX_TRY_NUMBER='2' AIRFLOW_CTX_DAG_RUN_ID='manual__2024-03-18T07:54:10.213408+00:00'
[2024-03-18T07:55:16.020+0000] {ssh.py:301} WARNING - No Host Key Verification. This won't protect against Man-In-The-Middle attacks
[2024-03-18T07:55:16.054+0000] {transport.py:1909} INFO - Connected (version 2.0, client OpenSSH_8.9p1)
[2024-03-18T07:55:16.286+0000] {transport.py:1909} INFO - Authentication (password) successful!
[2024-03-18T07:55:16.379+0000] {sftp.py:169} INFO - [chan 0] Opened sftp connection (server version 3)
[2024-03-18T07:55:16.382+0000] {ssh.py:301} WARNING - No Host Key Verification. This won't protect against Man-In-The-Middle attacks
[2024-03-18T07:55:16.396+0000] {transport.py:1909} INFO - Connected (version 2.0, client OpenSSH_8.9p1)
[2024-03-18T07:55:16.522+0000] {transport.py:1909} INFO - Authentication (password) successful!
[2024-03-18T07:55:16.606+0000] {sftp.py:169} INFO - [chan 0] Opened sftp connection (server version 3)
[2024-03-18T07:55:16.609+0000] {logging_mixin.py:188} INFO - ['file1.txt']
[2024-03-18T07:55:16.611+0000] {logging_mixin.py:188} INFO - Transforming files...
[2024-03-18T07:55:16.614+0000] {taskinstance.py:2731} ERROR - Task failed with exception
Traceback (most recent call last):
  File "/home/airflow/.local/lib/python3.8/site-packages/airflow/models/taskinstance.py", line 444, in _execute_task
    result = _execute_callable(context=context, **execute_callable_kwargs)
  File "/home/airflow/.local/lib/python3.8/site-packages/airflow/models/taskinstance.py", line 414, in _execute_callable
    return execute_callable(context=context, **execute_callable_kwargs)
  File "/home/airflow/.local/lib/python3.8/site-packages/airflow/operators/python.py", line 200, in execute
    return_value = self.execute_callable()
  File "/home/airflow/.local/lib/python3.8/site-packages/airflow/operators/python.py", line 217, in execute_callable
    return self.python_callable(*self.op_args, **self.op_kwargs)
  File "/opt/airflow/dags/sftp_sync_between_source_and_target.py", line 25, in sync_files
    dest_hook.store_file(f'/tmp/{file}', f'/home/airflow/filesystem/{file}')
  File "/home/airflow/.local/lib/python3.8/site-packages/airflow/providers/sftp/hooks/sftp.py", line 256, in store_file
    conn.put(local_full_path, remote_full_path, confirm=confirm)
  File "/home/airflow/.local/lib/python3.8/site-packages/paramiko/sftp_client.py", line 757, in put
    file_size = os.stat(localpath).st_size
FileNotFoundError: [Errno 2] No such file or directory: '/home/airflow/filesystem/file1.txt'
[2024-03-18T07:55:16.649+0000] {taskinstance.py:1149} INFO - Marking task as UP_FOR_RETRY. dag_id=sftp_sync, task_id=sync_files_task, execution_date=20240318T075410, start_date=20240318T075515, end_date=20240318T075516
[2024-03-18T07:55:16.683+0000] {standard_task_runner.py:107} ERROR - Failed to execute job 76 for task sync_files_task ([Errno 2] No such file or directory: '/home/airflow/filesystem/file1.txt'; 1201)
[2024-03-18T07:55:16.752+0000] {local_task_job_runner.py:234} INFO - Task exited with return code 1
[2024-03-18T07:55:16.814+0000] {taskinstance.py:3312} INFO - 0 downstream tasks scheduled from follow-on schedule check
