[2024-03-18T05:40:42.772+0000] {taskinstance.py:1979} INFO - Dependencies all met for dep_context=non-requeueable deps ti=<TaskInstance: sftp_sync.sync_files_task manual__2024-03-18T05:40:12.901174+00:00 [queued]>
[2024-03-18T05:40:42.818+0000] {taskinstance.py:1979} INFO - Dependencies all met for dep_context=requeueable deps ti=<TaskInstance: sftp_sync.sync_files_task manual__2024-03-18T05:40:12.901174+00:00 [queued]>
[2024-03-18T05:40:42.820+0000] {taskinstance.py:2193} INFO - Starting attempt 1 of 2
[2024-03-18T05:40:42.900+0000] {taskinstance.py:2217} INFO - Executing <Task(PythonOperator): sync_files_task> on 2024-03-18 05:40:12.901174+00:00
[2024-03-18T05:40:42.958+0000] {standard_task_runner.py:60} INFO - Started process 113 to run task
[2024-03-18T05:40:42.980+0000] {standard_task_runner.py:87} INFO - Running: ['***', 'tasks', 'run', 'sftp_sync', 'sync_files_task', 'manual__2024-03-18T05:40:12.901174+00:00', '--job-id', '66', '--raw', '--subdir', 'DAGS_FOLDER/sftp_sync_between_source_and_target.py', '--cfg-path', '/tmp/tmpxbx1bf1f']
[2024-03-18T05:40:42.996+0000] {standard_task_runner.py:88} INFO - Job 66: Subtask sync_files_task
[2024-03-18T05:40:43.253+0000] {task_command.py:423} INFO - Running <TaskInstance: sftp_sync.sync_files_task manual__2024-03-18T05:40:12.901174+00:00 [running]> on host fa05d1b87173
[2024-03-18T05:40:43.543+0000] {taskinstance.py:2513} INFO - Exporting env vars: AIRFLOW_CTX_DAG_OWNER='***' AIRFLOW_CTX_DAG_ID='sftp_sync' AIRFLOW_CTX_TASK_ID='sync_files_task' AIRFLOW_CTX_EXECUTION_DATE='2024-03-18T05:40:12.901174+00:00' AIRFLOW_CTX_TRY_NUMBER='1' AIRFLOW_CTX_DAG_RUN_ID='manual__2024-03-18T05:40:12.901174+00:00'
[2024-03-18T05:40:43.552+0000] {ssh.py:301} WARNING - No Host Key Verification. This won't protect against Man-In-The-Middle attacks
[2024-03-18T05:40:43.623+0000] {transport.py:1909} INFO - Connected (version 2.0, client OpenSSH_8.9p1)
[2024-03-18T05:40:43.859+0000] {transport.py:1909} INFO - Authentication (password) successful!
[2024-03-18T05:40:43.964+0000] {sftp.py:169} INFO - [chan 0] Opened sftp connection (server version 3)
[2024-03-18T05:40:43.986+0000] {ssh.py:301} WARNING - No Host Key Verification. This won't protect against Man-In-The-Middle attacks
[2024-03-18T05:40:44.004+0000] {ssh.py:343} INFO - Failed to connect. Sleeping before retry attempt 1
[2024-03-18T05:40:48.659+0000] {ssh.py:343} INFO - Failed to connect. Sleeping before retry attempt 2
[2024-03-18T05:40:53.950+0000] {taskinstance.py:2731} ERROR - Task failed with exception
Traceback (most recent call last):
  File "/home/airflow/.local/lib/python3.8/site-packages/airflow/models/taskinstance.py", line 444, in _execute_task
    result = _execute_callable(context=context, **execute_callable_kwargs)
  File "/home/airflow/.local/lib/python3.8/site-packages/airflow/models/taskinstance.py", line 414, in _execute_callable
    return execute_callable(context=context, **execute_callable_kwargs)
  File "/home/airflow/.local/lib/python3.8/site-packages/airflow/operators/python.py", line 200, in execute
    return_value = self.execute_callable()
  File "/home/airflow/.local/lib/python3.8/site-packages/airflow/operators/python.py", line 217, in execute_callable
    return self.python_callable(*self.op_args, **self.op_kwargs)
  File "/opt/airflow/dags/sftp_sync_between_source_and_target.py", line 18, in sync_files
    dest_files = dest_hook.list_directory('/home/airflow/filesystem/')
  File "/home/airflow/.local/lib/python3.8/site-packages/airflow/providers/sftp/hooks/sftp.py", line 160, in list_directory
    conn = self.get_conn()
  File "/home/airflow/.local/lib/python3.8/site-packages/airflow/providers/sftp/hooks/sftp.py", line 126, in get_conn
    self.conn = super().get_conn().open_sftp()
  File "/home/airflow/.local/lib/python3.8/site-packages/airflow/providers/ssh/hooks/ssh.py", line 347, in get_conn
    for attempt in Retrying(
  File "/home/airflow/.local/lib/python3.8/site-packages/tenacity/__init__.py", line 347, in __iter__
    do = self.iter(retry_state=retry_state)
  File "/home/airflow/.local/lib/python3.8/site-packages/tenacity/__init__.py", line 325, in iter
    raise retry_exc.reraise()
  File "/home/airflow/.local/lib/python3.8/site-packages/tenacity/__init__.py", line 158, in reraise
    raise self.last_attempt.result()
  File "/usr/local/lib/python3.8/concurrent/futures/_base.py", line 437, in result
    return self.__get_result()
  File "/usr/local/lib/python3.8/concurrent/futures/_base.py", line 389, in __get_result
    raise self._exception
  File "/home/airflow/.local/lib/python3.8/site-packages/airflow/providers/ssh/hooks/ssh.py", line 354, in get_conn
    client.connect(**connect_kwargs)
  File "/home/airflow/.local/lib/python3.8/site-packages/paramiko/client.py", line 409, in connect
    raise NoValidConnectionsError(errors)
paramiko.ssh_exception.NoValidConnectionsError: [Errno None] Unable to connect to port 22 on 192.168.80.10
[2024-03-18T05:40:54.731+0000] {taskinstance.py:1149} INFO - Marking task as UP_FOR_RETRY. dag_id=sftp_sync, task_id=sync_files_task, execution_date=20240318T054012, start_date=20240318T054042, end_date=20240318T054054
[2024-03-18T05:40:54.939+0000] {standard_task_runner.py:107} ERROR - Failed to execute job 66 for task sync_files_task ([Errno None] Unable to connect to port 22 on 192.168.80.10; 113)
[2024-03-18T05:40:55.462+0000] {local_task_job_runner.py:234} INFO - Task exited with return code 1
[2024-03-18T05:40:56.075+0000] {taskinstance.py:3312} INFO - 0 downstream tasks scheduled from follow-on schedule check
