[2024-03-18T04:30:07.147+0000] {taskinstance.py:1979} INFO - Dependencies all met for dep_context=non-requeueable deps ti=<TaskInstance: sftp_sync.sftp_sensor_task scheduled__2024-03-15T01:00:00+00:00 [queued]>
[2024-03-18T04:30:13.320+0000] {taskinstance.py:1979} INFO - Dependencies all met for dep_context=requeueable deps ti=<TaskInstance: sftp_sync.sftp_sensor_task scheduled__2024-03-15T01:00:00+00:00 [queued]>
[2024-03-18T04:30:13.468+0000] {taskinstance.py:2193} INFO - Starting attempt 1 of 2
[2024-03-18T04:30:25.188+0000] {taskinstance.py:2217} INFO - Executing <Task(SFTPSensor): sftp_sensor_task> on 2024-03-15 01:00:00+00:00
[2024-03-18T04:30:25.838+0000] {standard_task_runner.py:87} INFO - Running: ['***', 'tasks', 'run', 'sftp_sync', 'sftp_sensor_task', 'scheduled__2024-03-15T01:00:00+00:00', '--job-id', '28', '--raw', '--subdir', 'DAGS_FOLDER/sftp_sync_between_source_and_target.py', '--cfg-path', '/tmp/tmpxcfbhp1u']
[2024-03-18T04:30:25.883+0000] {standard_task_runner.py:88} INFO - Job 28: Subtask sftp_sensor_task
[2024-03-18T04:30:25.831+0000] {standard_task_runner.py:60} INFO - Started process 202 to run task
[2024-03-18T04:30:28.911+0000] {task_command.py:423} INFO - Running <TaskInstance: sftp_sync.sftp_sensor_task scheduled__2024-03-15T01:00:00+00:00 [running]> on host 78c95bc5c908
[2024-03-18T04:30:30.444+0000] {taskinstance.py:2513} INFO - Exporting env vars: AIRFLOW_CTX_DAG_OWNER='***' AIRFLOW_CTX_DAG_ID='sftp_sync' AIRFLOW_CTX_TASK_ID='sftp_sensor_task' AIRFLOW_CTX_EXECUTION_DATE='2024-03-15T01:00:00+00:00' AIRFLOW_CTX_TRY_NUMBER='1' AIRFLOW_CTX_DAG_RUN_ID='scheduled__2024-03-15T01:00:00+00:00'
[2024-03-18T04:30:30.616+0000] {base.py:83} INFO - Using connection ID 'source_sftp' for task execution.
[2024-03-18T04:30:30.638+0000] {sftp.py:80} INFO - Poking for /path/to/monitor, with pattern 
[2024-03-18T04:30:30.680+0000] {ssh.py:301} WARNING - No Host Key Verification. This won't protect against Man-In-The-Middle attacks
[2024-03-18T04:30:30.870+0000] {transport.py:1909} INFO - Connected (version 2.0, client OpenSSH_8.9p1)
[2024-03-18T04:30:32.614+0000] {transport.py:1909} INFO - Authentication (password) successful!
[2024-03-18T04:30:32.835+0000] {sftp.py:169} INFO - [chan 0] Opened sftp connection (server version 3)
[2024-03-18T04:30:32.871+0000] {sftp.py:169} INFO - [chan 0] sftp session closed.
[2024-03-18T04:30:54.091+0000] {local_task_job_runner.py:302} WARNING - State of this instance has been externally set to None. Terminating instance.
[2024-03-18T04:30:54.232+0000] {process_utils.py:131} INFO - Sending 15 to group 202. PIDs of all processes in the group: [202]
[2024-03-18T04:30:54.243+0000] {process_utils.py:86} INFO - Sending the signal 15 to group 202
[2024-03-18T04:30:54.262+0000] {taskinstance.py:2483} ERROR - Received SIGTERM. Terminating subprocesses.
[2024-03-18T04:30:54.592+0000] {taskinstance.py:2731} ERROR - Task failed with exception
Traceback (most recent call last):
  File "/home/airflow/.local/lib/python3.8/site-packages/airflow/models/taskinstance.py", line 444, in _execute_task
    result = _execute_callable(context=context, **execute_callable_kwargs)
  File "/home/airflow/.local/lib/python3.8/site-packages/airflow/models/taskinstance.py", line 414, in _execute_callable
    return execute_callable(context=context, **execute_callable_kwargs)
  File "/home/airflow/.local/lib/python3.8/site-packages/airflow/providers/sftp/sensors/sftp.py", line 154, in execute
    return super().execute(context=context)
  File "/home/airflow/.local/lib/python3.8/site-packages/airflow/sensors/base.py", line 293, in execute
    time.sleep(self._get_next_poke_interval(started_at, run_duration, try_number))
  File "/home/airflow/.local/lib/python3.8/site-packages/airflow/models/taskinstance.py", line 2485, in signal_handler
    raise AirflowException("Task received SIGTERM signal")
airflow.exceptions.AirflowException: Task received SIGTERM signal
[2024-03-18T04:30:54.665+0000] {taskinstance.py:1149} INFO - Marking task as FAILED. dag_id=sftp_sync, task_id=sftp_sensor_task, execution_date=20240315T010000, start_date=20240318T043007, end_date=20240318T043054
[2024-03-18T04:30:55.068+0000] {standard_task_runner.py:107} ERROR - Failed to execute job 28 for task sftp_sensor_task ((psycopg2.errors.ForeignKeyViolation) insert or update on table "task_fail" violates foreign key constraint "task_fail_ti_fkey"
DETAIL:  Key (dag_id, task_id, run_id, map_index)=(sftp_sync, sftp_sensor_task, scheduled__2024-03-15T01:00:00+00:00, -1) is not present in table "task_instance".

[SQL: INSERT INTO task_fail (task_id, dag_id, run_id, map_index, start_date, end_date, duration) VALUES (%(task_id)s, %(dag_id)s, %(run_id)s, %(map_index)s, %(start_date)s, %(end_date)s, %(duration)s) RETURNING task_fail.id]
[parameters: {'task_id': 'sftp_sensor_task', 'dag_id': 'sftp_sync', 'run_id': 'scheduled__2024-03-15T01:00:00+00:00', 'map_index': -1, 'start_date': datetime.datetime(2024, 3, 18, 4, 30, 7, 660223, tzinfo=Timezone('UTC')), 'end_date': datetime.datetime(2024, 3, 18, 4, 30, 54, 627518, tzinfo=Timezone('UTC')), 'duration': 46}]
(Background on this error at: https://sqlalche.me/e/14/gkpj); 202)
[2024-03-18T04:30:55.268+0000] {process_utils.py:79} INFO - Process psutil.Process(pid=202, status='terminated', exitcode=1, started='04:30:25') (202) terminated with exit code 1
[2024-03-18T04:31:50.392+0000] {taskinstance.py:1979} INFO - Dependencies all met for dep_context=non-requeueable deps ti=<TaskInstance: sftp_sync.sftp_sensor_task scheduled__2024-03-15T01:00:00+00:00 [queued]>
[2024-03-18T04:31:50.596+0000] {taskinstance.py:1979} INFO - Dependencies all met for dep_context=requeueable deps ti=<TaskInstance: sftp_sync.sftp_sensor_task scheduled__2024-03-15T01:00:00+00:00 [queued]>
[2024-03-18T04:31:50.606+0000] {taskinstance.py:2193} INFO - Starting attempt 1 of 2
[2024-03-18T04:31:51.050+0000] {taskinstance.py:2217} INFO - Executing <Task(SFTPSensor): sftp_sensor_task> on 2024-03-15 01:00:00+00:00
[2024-03-18T04:31:51.365+0000] {standard_task_runner.py:60} INFO - Started process 348 to run task
[2024-03-18T04:31:51.754+0000] {standard_task_runner.py:87} INFO - Running: ['***', 'tasks', 'run', 'sftp_sync', 'sftp_sensor_task', 'scheduled__2024-03-15T01:00:00+00:00', '--job-id', '36', '--raw', '--subdir', 'DAGS_FOLDER/sftp_sync_between_source_and_target.py', '--cfg-path', '/tmp/tmp0o5bzsxg']
[2024-03-18T04:31:51.804+0000] {standard_task_runner.py:88} INFO - Job 36: Subtask sftp_sensor_task
[2024-03-18T04:31:53.049+0000] {task_command.py:423} INFO - Running <TaskInstance: sftp_sync.sftp_sensor_task scheduled__2024-03-15T01:00:00+00:00 [running]> on host 78c95bc5c908
[2024-03-18T04:31:54.148+0000] {taskinstance.py:2513} INFO - Exporting env vars: AIRFLOW_CTX_DAG_OWNER='***' AIRFLOW_CTX_DAG_ID='sftp_sync' AIRFLOW_CTX_TASK_ID='sftp_sensor_task' AIRFLOW_CTX_EXECUTION_DATE='2024-03-15T01:00:00+00:00' AIRFLOW_CTX_TRY_NUMBER='1' AIRFLOW_CTX_DAG_RUN_ID='scheduled__2024-03-15T01:00:00+00:00'
[2024-03-18T04:31:54.233+0000] {base.py:83} INFO - Using connection ID 'source_sftp' for task execution.
[2024-03-18T04:31:54.240+0000] {sftp.py:80} INFO - Poking for /path/to/monitor, with pattern 
[2024-03-18T04:31:54.248+0000] {ssh.py:301} WARNING - No Host Key Verification. This won't protect against Man-In-The-Middle attacks
[2024-03-18T04:31:54.308+0000] {transport.py:1909} INFO - Connected (version 2.0, client OpenSSH_8.9p1)
[2024-03-18T04:31:54.968+0000] {transport.py:1909} INFO - Authentication (password) successful!
[2024-03-18T04:31:55.058+0000] {sftp.py:169} INFO - [chan 0] Opened sftp connection (server version 3)
[2024-03-18T04:31:55.073+0000] {sftp.py:169} INFO - [chan 0] sftp session closed.
[2024-03-18T04:32:36.189+0000] {base.py:83} INFO - Using connection ID 'source_sftp' for task execution.
[2024-03-18T04:32:36.459+0000] {sftp.py:80} INFO - Poking for /path/to/monitor, with pattern 
[2024-03-18T04:32:36.563+0000] {ssh.py:301} WARNING - No Host Key Verification. This won't protect against Man-In-The-Middle attacks
[2024-03-18T04:32:48.202+0000] {ssh.py:343} INFO - Failed to connect. Sleeping before retry attempt 1
[2024-03-18T04:33:02.706+0000] {ssh.py:343} INFO - Failed to connect. Sleeping before retry attempt 2
[2024-03-18T04:32:57.326+0000] {job.py:213} ERROR - Job heartbeat got an exception
Traceback (most recent call last):
  File "/home/airflow/.local/lib/python3.8/site-packages/sqlalchemy/engine/base.py", line 3371, in _wrap_pool_connect
    return fn()
  File "/home/airflow/.local/lib/python3.8/site-packages/sqlalchemy/pool/base.py", line 327, in connect
    return _ConnectionFairy._checkout(self)
  File "/home/airflow/.local/lib/python3.8/site-packages/sqlalchemy/pool/base.py", line 894, in _checkout
    fairy = _ConnectionRecord.checkout(pool)
  File "/home/airflow/.local/lib/python3.8/site-packages/sqlalchemy/pool/base.py", line 493, in checkout
    rec = pool._do_get()
  File "/home/airflow/.local/lib/python3.8/site-packages/sqlalchemy/pool/impl.py", line 256, in _do_get
    return self._create_connection()
  File "/home/airflow/.local/lib/python3.8/site-packages/sqlalchemy/pool/base.py", line 273, in _create_connection
    return _ConnectionRecord(self)
  File "/home/airflow/.local/lib/python3.8/site-packages/sqlalchemy/pool/base.py", line 388, in __init__
    self.__connect()
  File "/home/airflow/.local/lib/python3.8/site-packages/sqlalchemy/pool/base.py", line 691, in __connect
    pool.logger.debug("Error on connect(): %s", e)
  File "/home/airflow/.local/lib/python3.8/site-packages/sqlalchemy/util/langhelpers.py", line 70, in __exit__
    compat.raise_(
  File "/home/airflow/.local/lib/python3.8/site-packages/sqlalchemy/util/compat.py", line 211, in raise_
    raise exception
  File "/home/airflow/.local/lib/python3.8/site-packages/sqlalchemy/pool/base.py", line 686, in __connect
    self.dbapi_connection = connection = pool._invoke_creator(self)
  File "/home/airflow/.local/lib/python3.8/site-packages/sqlalchemy/engine/create.py", line 574, in connect
    return dialect.connect(*cargs, **cparams)
  File "/home/airflow/.local/lib/python3.8/site-packages/sqlalchemy/engine/default.py", line 598, in connect
    return self.dbapi.connect(*cargs, **cparams)
  File "/home/airflow/.local/lib/python3.8/site-packages/psycopg2/__init__.py", line 122, in connect
    conn = _connect(dsn, connection_factory=connection_factory, **kwasync)
psycopg2.OperationalError: could not translate host name "postgres" to address: Temporary failure in name resolution


The above exception was the direct cause of the following exception:

Traceback (most recent call last):
  File "/home/airflow/.local/lib/python3.8/site-packages/airflow/jobs/job.py", line 187, in heartbeat
    self._merge_from(Job._fetch_from_db(self, session))
  File "/home/airflow/.local/lib/python3.8/site-packages/airflow/api_internal/internal_api_call.py", line 114, in wrapper
    return func(*args, **kwargs)
  File "/home/airflow/.local/lib/python3.8/site-packages/airflow/utils/session.py", line 76, in wrapper
    return func(*args, **kwargs)
  File "/home/airflow/.local/lib/python3.8/site-packages/airflow/jobs/job.py", line 308, in _fetch_from_db
    session.merge(job)
  File "/home/airflow/.local/lib/python3.8/site-packages/sqlalchemy/orm/session.py", line 3056, in merge
    return self._merge(
  File "/home/airflow/.local/lib/python3.8/site-packages/sqlalchemy/orm/session.py", line 3136, in _merge
    merged = self.get(
  File "/home/airflow/.local/lib/python3.8/site-packages/sqlalchemy/orm/session.py", line 2853, in get
    return self._get_impl(
  File "/home/airflow/.local/lib/python3.8/site-packages/sqlalchemy/orm/session.py", line 2975, in _get_impl
    return db_load_fn(
  File "/home/airflow/.local/lib/python3.8/site-packages/sqlalchemy/orm/loading.py", line 530, in load_on_pk_identity
    session.execute(
  File "/home/airflow/.local/lib/python3.8/site-packages/sqlalchemy/orm/session.py", line 1716, in execute
    conn = self._connection_for_bind(bind)
  File "/home/airflow/.local/lib/python3.8/site-packages/sqlalchemy/orm/session.py", line 1555, in _connection_for_bind
    return self._transaction._connection_for_bind(
  File "/home/airflow/.local/lib/python3.8/site-packages/sqlalchemy/orm/session.py", line 750, in _connection_for_bind
    conn = bind.connect()
  File "/home/airflow/.local/lib/python3.8/site-packages/sqlalchemy/future/engine.py", line 412, in connect
    return super(Engine, self).connect()
  File "/home/airflow/.local/lib/python3.8/site-packages/sqlalchemy/engine/base.py", line 3325, in connect
    return self._connection_cls(self, close_with_result=close_with_result)
  File "/home/airflow/.local/lib/python3.8/site-packages/sqlalchemy/engine/base.py", line 96, in __init__
    else engine.raw_connection()
  File "/home/airflow/.local/lib/python3.8/site-packages/sqlalchemy/engine/base.py", line 3404, in raw_connection
    return self._wrap_pool_connect(self.pool.connect, _connection)
  File "/home/airflow/.local/lib/python3.8/site-packages/sqlalchemy/engine/base.py", line 3374, in _wrap_pool_connect
    Connection._handle_dbapi_exception_noconnection(
  File "/home/airflow/.local/lib/python3.8/site-packages/sqlalchemy/engine/base.py", line 2208, in _handle_dbapi_exception_noconnection
    util.raise_(
  File "/home/airflow/.local/lib/python3.8/site-packages/sqlalchemy/util/compat.py", line 211, in raise_
    raise exception
  File "/home/airflow/.local/lib/python3.8/site-packages/sqlalchemy/engine/base.py", line 3371, in _wrap_pool_connect
    return fn()
  File "/home/airflow/.local/lib/python3.8/site-packages/sqlalchemy/pool/base.py", line 327, in connect
    return _ConnectionFairy._checkout(self)
  File "/home/airflow/.local/lib/python3.8/site-packages/sqlalchemy/pool/base.py", line 894, in _checkout
    fairy = _ConnectionRecord.checkout(pool)
  File "/home/airflow/.local/lib/python3.8/site-packages/sqlalchemy/pool/base.py", line 493, in checkout
    rec = pool._do_get()
  File "/home/airflow/.local/lib/python3.8/site-packages/sqlalchemy/pool/impl.py", line 256, in _do_get
    return self._create_connection()
  File "/home/airflow/.local/lib/python3.8/site-packages/sqlalchemy/pool/base.py", line 273, in _create_connection
    return _ConnectionRecord(self)
  File "/home/airflow/.local/lib/python3.8/site-packages/sqlalchemy/pool/base.py", line 388, in __init__
    self.__connect()
  File "/home/airflow/.local/lib/python3.8/site-packages/sqlalchemy/pool/base.py", line 691, in __connect
    pool.logger.debug("Error on connect(): %s", e)
  File "/home/airflow/.local/lib/python3.8/site-packages/sqlalchemy/util/langhelpers.py", line 70, in __exit__
    compat.raise_(
  File "/home/airflow/.local/lib/python3.8/site-packages/sqlalchemy/util/compat.py", line 211, in raise_
    raise exception
  File "/home/airflow/.local/lib/python3.8/site-packages/sqlalchemy/pool/base.py", line 686, in __connect
    self.dbapi_connection = connection = pool._invoke_creator(self)
  File "/home/airflow/.local/lib/python3.8/site-packages/sqlalchemy/engine/create.py", line 574, in connect
    return dialect.connect(*cargs, **cparams)
  File "/home/airflow/.local/lib/python3.8/site-packages/sqlalchemy/engine/default.py", line 598, in connect
    return self.dbapi.connect(*cargs, **cparams)
  File "/home/airflow/.local/lib/python3.8/site-packages/psycopg2/__init__.py", line 122, in connect
    conn = _connect(dsn, connection_factory=connection_factory, **kwasync)
sqlalchemy.exc.OperationalError: (psycopg2.OperationalError) could not translate host name "postgres" to address: Temporary failure in name resolution

(Background on this error at: https://sqlalche.me/e/14/e3q8)
[2024-03-18T04:33:05.651+0000] {job.py:221} ERROR - Job heartbeat failed with error. Scheduler is in unhealthy state
[2024-03-18T04:33:06.667+0000] {transport.py:1909} INFO - Connected (version 2.0, client OpenSSH_8.9p1)
[2024-03-18T04:33:19.306+0000] {taskinstance.py:2731} ERROR - Task failed with exception
Traceback (most recent call last):
  File "/home/airflow/.local/lib/python3.8/site-packages/airflow/models/taskinstance.py", line 444, in _execute_task
    result = _execute_callable(context=context, **execute_callable_kwargs)
  File "/home/airflow/.local/lib/python3.8/site-packages/airflow/models/taskinstance.py", line 414, in _execute_callable
    return execute_callable(context=context, **execute_callable_kwargs)
  File "/home/airflow/.local/lib/python3.8/site-packages/airflow/providers/sftp/sensors/sftp.py", line 154, in execute
    return super().execute(context=context)
  File "/home/airflow/.local/lib/python3.8/site-packages/airflow/sensors/base.py", line 265, in execute
    raise e
  File "/home/airflow/.local/lib/python3.8/site-packages/airflow/sensors/base.py", line 247, in execute
    poke_return = self.poke(context)
  File "/home/airflow/.local/lib/python3.8/site-packages/airflow/providers/sftp/sensors/sftp.py", line 96, in poke
    mod_time = self.hook.get_mod_time(actual_file_to_check)
  File "/home/airflow/.local/lib/python3.8/site-packages/airflow/providers/sftp/hooks/sftp.py", line 271, in get_mod_time
    conn = self.get_conn()
  File "/home/airflow/.local/lib/python3.8/site-packages/airflow/providers/sftp/hooks/sftp.py", line 126, in get_conn
    self.conn = super().get_conn().open_sftp()
  File "/home/airflow/.local/lib/python3.8/site-packages/airflow/providers/ssh/hooks/ssh.py", line 347, in get_conn
    for attempt in Retrying(
  File "/home/airflow/.local/lib/python3.8/site-packages/tenacity/__init__.py", line 347, in __iter__
    do = self.iter(retry_state=retry_state)
  File "/home/airflow/.local/lib/python3.8/site-packages/tenacity/__init__.py", line 325, in iter
    raise retry_exc.reraise()
  File "/home/airflow/.local/lib/python3.8/site-packages/tenacity/__init__.py", line 158, in reraise
    raise self.last_attempt.result()
  File "/usr/local/lib/python3.8/concurrent/futures/_base.py", line 437, in result
    return self.__get_result()
  File "/usr/local/lib/python3.8/concurrent/futures/_base.py", line 389, in __get_result
    raise self._exception
  File "/home/airflow/.local/lib/python3.8/site-packages/airflow/providers/ssh/hooks/ssh.py", line 354, in get_conn
    client.connect(**connect_kwargs)
  File "/home/airflow/.local/lib/python3.8/site-packages/paramiko/client.py", line 457, in connect
    server_key = t.get_remote_server_key()
  File "/home/airflow/.local/lib/python3.8/site-packages/paramiko/transport.py", line 918, in get_remote_server_key
    raise SSHException("No existing session")
paramiko.ssh_exception.SSHException: No existing session
[2024-03-18T04:33:22.117+0000] {job.py:221} ERROR - Job heartbeat failed with error. Scheduler is in unhealthy state
[2024-03-18T04:33:20.033+0000] {transport.py:1909} INFO - Connected (version 2.0, client OpenSSH_8.9p1)
[2024-03-18T04:33:47.725+0000] {job.py:221} ERROR - Job heartbeat failed with error. Scheduler is in unhealthy state
[2024-03-18T04:33:48.190+0000] {standard_task_runner.py:107} ERROR - Failed to execute job 36 for task sftp_sensor_task ((psycopg2.OperationalError) could not translate host name "postgres" to address: Temporary failure in name resolution

(Background on this error at: https://sqlalche.me/e/14/e3q8); 348)
[2024-03-18T04:33:49.891+0000] {local_task_job_runner.py:234} INFO - Task exited with return code 1
[2024-03-18T04:33:54.974+0000] {taskinstance.py:3312} INFO - 0 downstream tasks scheduled from follow-on schedule check
