[2024-03-18T04:42:37.410+0000] {taskinstance.py:1979} INFO - Dependencies all met for dep_context=non-requeueable deps ti=<TaskInstance: sftp_sync.sync_files_task manual__2024-03-18T04:42:31.334505+00:00 [queued]>
[2024-03-18T04:42:37.427+0000] {taskinstance.py:1979} INFO - Dependencies all met for dep_context=requeueable deps ti=<TaskInstance: sftp_sync.sync_files_task manual__2024-03-18T04:42:31.334505+00:00 [queued]>
[2024-03-18T04:42:37.433+0000] {taskinstance.py:2193} INFO - Starting attempt 1 of 2
[2024-03-18T04:42:37.463+0000] {taskinstance.py:2217} INFO - Executing <Task(PythonOperator): sync_files_task> on 2024-03-18 04:42:31.334505+00:00
[2024-03-18T04:42:37.479+0000] {standard_task_runner.py:60} INFO - Started process 550 to run task
[2024-03-18T04:42:37.493+0000] {standard_task_runner.py:87} INFO - Running: ['***', 'tasks', 'run', 'sftp_sync', 'sync_files_task', 'manual__2024-03-18T04:42:31.334505+00:00', '--job-id', '43', '--raw', '--subdir', 'DAGS_FOLDER/sftp_sync_between_source_and_target.py', '--cfg-path', '/tmp/tmpdolxupgt']
[2024-03-18T04:42:37.496+0000] {standard_task_runner.py:88} INFO - Job 43: Subtask sync_files_task
[2024-03-18T04:42:37.591+0000] {task_command.py:423} INFO - Running <TaskInstance: sftp_sync.sync_files_task manual__2024-03-18T04:42:31.334505+00:00 [running]> on host 78c95bc5c908
[2024-03-18T04:42:37.725+0000] {taskinstance.py:2513} INFO - Exporting env vars: AIRFLOW_CTX_DAG_OWNER='***' AIRFLOW_CTX_DAG_ID='sftp_sync' AIRFLOW_CTX_TASK_ID='sync_files_task' AIRFLOW_CTX_EXECUTION_DATE='2024-03-18T04:42:31.334505+00:00' AIRFLOW_CTX_TRY_NUMBER='1' AIRFLOW_CTX_DAG_RUN_ID='manual__2024-03-18T04:42:31.334505+00:00'
[2024-03-18T04:42:37.728+0000] {taskinstance.py:2731} ERROR - Task failed with exception
Traceback (most recent call last):
  File "/home/airflow/.local/lib/python3.8/site-packages/airflow/models/taskinstance.py", line 444, in _execute_task
    result = _execute_callable(context=context, **execute_callable_kwargs)
  File "/home/airflow/.local/lib/python3.8/site-packages/airflow/models/taskinstance.py", line 414, in _execute_callable
    return execute_callable(context=context, **execute_callable_kwargs)
  File "/home/airflow/.local/lib/python3.8/site-packages/airflow/operators/python.py", line 200, in execute
    return_value = self.execute_callable()
  File "/home/airflow/.local/lib/python3.8/site-packages/airflow/operators/python.py", line 217, in execute_callable
    return self.python_callable(*self.op_args, **self.op_kwargs)
  File "/opt/airflow/dags/sftp_sync_between_source_and_target.py", line 13, in sync_files
    source_files = source_hook.list_directory()
TypeError: list_directory() missing 1 required positional argument: 'path'
[2024-03-18T04:42:37.739+0000] {taskinstance.py:1149} INFO - Marking task as UP_FOR_RETRY. dag_id=sftp_sync, task_id=sync_files_task, execution_date=20240318T044231, start_date=20240318T044237, end_date=20240318T044237
[2024-03-18T04:42:37.755+0000] {standard_task_runner.py:107} ERROR - Failed to execute job 43 for task sync_files_task (list_directory() missing 1 required positional argument: 'path'; 550)
[2024-03-18T04:42:37.799+0000] {local_task_job_runner.py:234} INFO - Task exited with return code 1
[2024-03-18T04:42:37.847+0000] {taskinstance.py:3312} INFO - 0 downstream tasks scheduled from follow-on schedule check
