[2024-03-17T19:41:08.935+0000] {taskinstance.py:1979} INFO - Dependencies all met for dep_context=non-requeueable deps ti=<TaskInstance: sftp_sync_between_source_and_target.waiting_for_new_file manual__2024-03-17T19:41:02.329809+00:00 [queued]>
[2024-03-17T19:41:09.017+0000] {taskinstance.py:1979} INFO - Dependencies all met for dep_context=requeueable deps ti=<TaskInstance: sftp_sync_between_source_and_target.waiting_for_new_file manual__2024-03-17T19:41:02.329809+00:00 [queued]>
[2024-03-17T19:41:09.019+0000] {taskinstance.py:2193} INFO - Starting attempt 1 of 2
[2024-03-17T19:41:09.103+0000] {taskinstance.py:2217} INFO - Executing <Task(SFTPSensor): waiting_for_new_file> on 2024-03-17 19:41:02.329809+00:00
[2024-03-17T19:41:09.247+0000] {standard_task_runner.py:60} INFO - Started process 414 to run task
[2024-03-17T19:41:09.259+0000] {standard_task_runner.py:87} INFO - Running: ['***', 'tasks', 'run', 'sftp_sync_between_source_and_target', 'waiting_for_new_file', 'manual__2024-03-17T19:41:02.329809+00:00', '--job-id', '16', '--raw', '--subdir', 'DAGS_FOLDER/stfp_pipeline.py', '--cfg-path', '/tmp/tmpyzxbkgmy']
[2024-03-17T19:41:09.264+0000] {standard_task_runner.py:88} INFO - Job 16: Subtask waiting_for_new_file
[2024-03-17T19:41:09.474+0000] {task_command.py:423} INFO - Running <TaskInstance: sftp_sync_between_source_and_target.waiting_for_new_file manual__2024-03-17T19:41:02.329809+00:00 [running]> on host b679b9e6d73a
[2024-03-17T19:41:09.667+0000] {taskinstance.py:2513} INFO - Exporting env vars: AIRFLOW_CTX_DAG_OWNER='***' AIRFLOW_CTX_DAG_ID='sftp_sync_between_source_and_target' AIRFLOW_CTX_TASK_ID='waiting_for_new_file' AIRFLOW_CTX_EXECUTION_DATE='2024-03-17T19:41:02.329809+00:00' AIRFLOW_CTX_TRY_NUMBER='1' AIRFLOW_CTX_DAG_RUN_ID='manual__2024-03-17T19:41:02.329809+00:00'
[2024-03-17T19:41:09.702+0000] {base.py:83} INFO - Using connection ID 'source_sftp' for task execution.
[2024-03-17T19:41:09.704+0000] {sftp.py:80} INFO - Poking for /filesystem, with pattern 
[2024-03-17T19:41:09.707+0000] {ssh.py:301} WARNING - No Host Key Verification. This won't protect against Man-In-The-Middle attacks
[2024-03-17T19:41:19.831+0000] {ssh.py:343} INFO - Failed to connect. Sleeping before retry attempt 1
[2024-03-17T19:41:34.226+0000] {ssh.py:343} INFO - Failed to connect. Sleeping before retry attempt 2
[2024-03-17T19:41:48.742+0000] {taskinstance.py:2731} ERROR - Task failed with exception
Traceback (most recent call last):
  File "/home/airflow/.local/lib/python3.8/site-packages/airflow/models/taskinstance.py", line 444, in _execute_task
    result = _execute_callable(context=context, **execute_callable_kwargs)
  File "/home/airflow/.local/lib/python3.8/site-packages/airflow/models/taskinstance.py", line 414, in _execute_callable
    return execute_callable(context=context, **execute_callable_kwargs)
  File "/home/airflow/.local/lib/python3.8/site-packages/airflow/providers/sftp/sensors/sftp.py", line 154, in execute
    return super().execute(context=context)
  File "/home/airflow/.local/lib/python3.8/site-packages/airflow/sensors/base.py", line 265, in execute
    raise e
  File "/home/airflow/.local/lib/python3.8/site-packages/airflow/sensors/base.py", line 247, in execute
    poke_return = self.poke(context)
  File "/home/airflow/.local/lib/python3.8/site-packages/airflow/providers/sftp/sensors/sftp.py", line 103, in poke
    raise e
  File "/home/airflow/.local/lib/python3.8/site-packages/airflow/providers/sftp/sensors/sftp.py", line 96, in poke
    mod_time = self.hook.get_mod_time(actual_file_to_check)
  File "/home/airflow/.local/lib/python3.8/site-packages/airflow/providers/sftp/hooks/sftp.py", line 271, in get_mod_time
    conn = self.get_conn()
  File "/home/airflow/.local/lib/python3.8/site-packages/airflow/providers/sftp/hooks/sftp.py", line 126, in get_conn
    self.conn = super().get_conn().open_sftp()
  File "/home/airflow/.local/lib/python3.8/site-packages/airflow/providers/ssh/hooks/ssh.py", line 347, in get_conn
    for attempt in Retrying(
  File "/home/airflow/.local/lib/python3.8/site-packages/tenacity/__init__.py", line 347, in __iter__
    do = self.iter(retry_state=retry_state)
  File "/home/airflow/.local/lib/python3.8/site-packages/tenacity/__init__.py", line 325, in iter
    raise retry_exc.reraise()
  File "/home/airflow/.local/lib/python3.8/site-packages/tenacity/__init__.py", line 158, in reraise
    raise self.last_attempt.result()
  File "/usr/local/lib/python3.8/concurrent/futures/_base.py", line 437, in result
    return self.__get_result()
  File "/usr/local/lib/python3.8/concurrent/futures/_base.py", line 389, in __get_result
    raise self._exception
  File "/home/airflow/.local/lib/python3.8/site-packages/airflow/providers/ssh/hooks/ssh.py", line 354, in get_conn
    client.connect(**connect_kwargs)
  File "/home/airflow/.local/lib/python3.8/site-packages/paramiko/client.py", line 386, in connect
    sock.connect(addr)
socket.timeout: timed out
[2024-03-17T19:41:48.865+0000] {taskinstance.py:1149} INFO - Marking task as UP_FOR_RETRY. dag_id=sftp_sync_between_source_and_target, task_id=waiting_for_new_file, execution_date=20240317T194102, start_date=20240317T194108, end_date=20240317T194148
[2024-03-17T19:41:48.910+0000] {standard_task_runner.py:107} ERROR - Failed to execute job 16 for task waiting_for_new_file (timed out; 414)
[2024-03-17T19:41:49.009+0000] {local_task_job_runner.py:234} INFO - Task exited with return code 1
[2024-03-17T19:41:49.090+0000] {taskinstance.py:3312} INFO - 0 downstream tasks scheduled from follow-on schedule check
