[2024-03-18T04:29:31.726+0000] {taskinstance.py:1979} INFO - Dependencies all met for dep_context=non-requeueable deps ti=<TaskInstance: sftp_sync.sftp_sensor_task scheduled__2024-03-15T00:00:00+00:00 [queued]>
[2024-03-18T04:29:31.797+0000] {taskinstance.py:1979} INFO - Dependencies all met for dep_context=requeueable deps ti=<TaskInstance: sftp_sync.sftp_sensor_task scheduled__2024-03-15T00:00:00+00:00 [queued]>
[2024-03-18T04:29:31.826+0000] {taskinstance.py:2193} INFO - Starting attempt 1 of 2
[2024-03-18T04:29:31.958+0000] {taskinstance.py:2217} INFO - Executing <Task(SFTPSensor): sftp_sensor_task> on 2024-03-15 00:00:00+00:00
[2024-03-18T04:29:32.056+0000] {standard_task_runner.py:60} INFO - Started process 101 to run task
[2024-03-18T04:29:32.092+0000] {standard_task_runner.py:87} INFO - Running: ['***', 'tasks', 'run', 'sftp_sync', 'sftp_sensor_task', 'scheduled__2024-03-15T00:00:00+00:00', '--job-id', '26', '--raw', '--subdir', 'DAGS_FOLDER/sftp_sync_between_source_and_target.py', '--cfg-path', '/tmp/tmpfsr_ojz7']
[2024-03-18T04:29:32.100+0000] {standard_task_runner.py:88} INFO - Job 26: Subtask sftp_sensor_task
[2024-03-18T04:29:32.766+0000] {task_command.py:423} INFO - Running <TaskInstance: sftp_sync.sftp_sensor_task scheduled__2024-03-15T00:00:00+00:00 [running]> on host 78c95bc5c908
[2024-03-18T04:29:33.250+0000] {taskinstance.py:2513} INFO - Exporting env vars: AIRFLOW_CTX_DAG_OWNER='***' AIRFLOW_CTX_DAG_ID='sftp_sync' AIRFLOW_CTX_TASK_ID='sftp_sensor_task' AIRFLOW_CTX_EXECUTION_DATE='2024-03-15T00:00:00+00:00' AIRFLOW_CTX_TRY_NUMBER='1' AIRFLOW_CTX_DAG_RUN_ID='scheduled__2024-03-15T00:00:00+00:00'
[2024-03-18T04:29:33.328+0000] {base.py:83} INFO - Using connection ID 'source_sftp' for task execution.
[2024-03-18T04:29:33.336+0000] {sftp.py:80} INFO - Poking for /path/to/monitor, with pattern 
[2024-03-18T04:29:33.368+0000] {ssh.py:301} WARNING - No Host Key Verification. This won't protect against Man-In-The-Middle attacks
[2024-03-18T04:29:33.584+0000] {transport.py:1909} INFO - Connected (version 2.0, client OpenSSH_8.9p1)
[2024-03-18T04:29:34.179+0000] {transport.py:1909} INFO - Authentication (password) successful!
[2024-03-18T04:29:34.363+0000] {sftp.py:169} INFO - [chan 0] Opened sftp connection (server version 3)
[2024-03-18T04:29:34.376+0000] {sftp.py:169} INFO - [chan 0] sftp session closed.
[2024-03-18T04:30:12.100+0000] {base.py:83} INFO - Using connection ID 'source_sftp' for task execution.
[2024-03-18T04:30:12.212+0000] {sftp.py:80} INFO - Poking for /path/to/monitor, with pattern 
[2024-03-18T04:30:12.244+0000] {ssh.py:301} WARNING - No Host Key Verification. This won't protect against Man-In-The-Middle attacks
[2024-03-18T04:30:22.641+0000] {ssh.py:343} INFO - Failed to connect. Sleeping before retry attempt 1
[2024-03-18T04:30:28.162+0000] {transport.py:1909} INFO - Connected (version 2.0, client OpenSSH_8.9p1)
[2024-03-18T04:30:29.134+0000] {transport.py:1909} INFO - Authentication (password) successful!
[2024-03-18T04:30:29.377+0000] {sftp.py:169} INFO - [chan 0] Opened sftp connection (server version 3)
[2024-03-18T04:30:29.435+0000] {sftp.py:169} INFO - [chan 0] sftp session closed.
[2024-03-18T04:30:54.135+0000] {local_task_job_runner.py:302} WARNING - State of this instance has been externally set to None. Terminating instance.
[2024-03-18T04:30:54.271+0000] {process_utils.py:131} INFO - Sending 15 to group 101. PIDs of all processes in the group: [101]
[2024-03-18T04:30:54.276+0000] {process_utils.py:86} INFO - Sending the signal 15 to group 101
[2024-03-18T04:30:54.301+0000] {taskinstance.py:2483} ERROR - Received SIGTERM. Terminating subprocesses.
[2024-03-18T04:30:54.590+0000] {taskinstance.py:2731} ERROR - Task failed with exception
Traceback (most recent call last):
  File "/home/airflow/.local/lib/python3.8/site-packages/airflow/models/taskinstance.py", line 444, in _execute_task
    result = _execute_callable(context=context, **execute_callable_kwargs)
  File "/home/airflow/.local/lib/python3.8/site-packages/airflow/models/taskinstance.py", line 414, in _execute_callable
    return execute_callable(context=context, **execute_callable_kwargs)
  File "/home/airflow/.local/lib/python3.8/site-packages/airflow/providers/sftp/sensors/sftp.py", line 154, in execute
    return super().execute(context=context)
  File "/home/airflow/.local/lib/python3.8/site-packages/airflow/sensors/base.py", line 293, in execute
    time.sleep(self._get_next_poke_interval(started_at, run_duration, try_number))
  File "/home/airflow/.local/lib/python3.8/site-packages/airflow/models/taskinstance.py", line 2485, in signal_handler
    raise AirflowException("Task received SIGTERM signal")
airflow.exceptions.AirflowException: Task received SIGTERM signal
[2024-03-18T04:30:54.706+0000] {taskinstance.py:1149} INFO - Marking task as FAILED. dag_id=sftp_sync, task_id=sftp_sensor_task, execution_date=20240315T000000, start_date=20240318T042931, end_date=20240318T043054
[2024-03-18T04:30:55.016+0000] {standard_task_runner.py:107} ERROR - Failed to execute job 26 for task sftp_sensor_task ((psycopg2.errors.ForeignKeyViolation) insert or update on table "task_fail" violates foreign key constraint "task_fail_ti_fkey"
DETAIL:  Key (dag_id, task_id, run_id, map_index)=(sftp_sync, sftp_sensor_task, scheduled__2024-03-15T00:00:00+00:00, -1) is not present in table "task_instance".

[SQL: INSERT INTO task_fail (task_id, dag_id, run_id, map_index, start_date, end_date, duration) VALUES (%(task_id)s, %(dag_id)s, %(run_id)s, %(map_index)s, %(start_date)s, %(end_date)s, %(duration)s) RETURNING task_fail.id]
[parameters: {'task_id': 'sftp_sensor_task', 'dag_id': 'sftp_sync', 'run_id': 'scheduled__2024-03-15T00:00:00+00:00', 'map_index': -1, 'start_date': datetime.datetime(2024, 3, 18, 4, 29, 31, 733076, tzinfo=Timezone('UTC')), 'end_date': datetime.datetime(2024, 3, 18, 4, 30, 54, 637189, tzinfo=Timezone('UTC')), 'duration': 82}]
(Background on this error at: https://sqlalche.me/e/14/gkpj); 101)
[2024-03-18T04:30:55.169+0000] {process_utils.py:79} INFO - Process psutil.Process(pid=101, status='terminated', exitcode=1, started='04:29:31') (101) terminated with exit code 1
[2024-03-18T04:31:16.511+0000] {taskinstance.py:1979} INFO - Dependencies all met for dep_context=non-requeueable deps ti=<TaskInstance: sftp_sync.sftp_sensor_task scheduled__2024-03-15T00:00:00+00:00 [queued]>
[2024-03-18T04:31:17.081+0000] {taskinstance.py:1979} INFO - Dependencies all met for dep_context=requeueable deps ti=<TaskInstance: sftp_sync.sftp_sensor_task scheduled__2024-03-15T00:00:00+00:00 [queued]>
[2024-03-18T04:31:17.169+0000] {taskinstance.py:2193} INFO - Starting attempt 1 of 2
[2024-03-18T04:31:17.671+0000] {taskinstance.py:2217} INFO - Executing <Task(SFTPSensor): sftp_sensor_task> on 2024-03-15 00:00:00+00:00
[2024-03-18T04:31:17.691+0000] {standard_task_runner.py:60} INFO - Started process 302 to run task
[2024-03-18T04:31:17.729+0000] {standard_task_runner.py:87} INFO - Running: ['***', 'tasks', 'run', 'sftp_sync', 'sftp_sensor_task', 'scheduled__2024-03-15T00:00:00+00:00', '--job-id', '33', '--raw', '--subdir', 'DAGS_FOLDER/sftp_sync_between_source_and_target.py', '--cfg-path', '/tmp/tmpt9tcz941']
[2024-03-18T04:31:17.733+0000] {standard_task_runner.py:88} INFO - Job 33: Subtask sftp_sensor_task
[2024-03-18T04:31:20.160+0000] {task_command.py:423} INFO - Running <TaskInstance: sftp_sync.sftp_sensor_task scheduled__2024-03-15T00:00:00+00:00 [running]> on host 78c95bc5c908
[2024-03-18T04:31:23.732+0000] {taskinstance.py:2513} INFO - Exporting env vars: AIRFLOW_CTX_DAG_OWNER='***' AIRFLOW_CTX_DAG_ID='sftp_sync' AIRFLOW_CTX_TASK_ID='sftp_sensor_task' AIRFLOW_CTX_EXECUTION_DATE='2024-03-15T00:00:00+00:00' AIRFLOW_CTX_TRY_NUMBER='1' AIRFLOW_CTX_DAG_RUN_ID='scheduled__2024-03-15T00:00:00+00:00'
[2024-03-18T04:31:45.154+0000] {base.py:83} INFO - Using connection ID 'source_sftp' for task execution.
[2024-03-18T04:31:45.806+0000] {sftp.py:80} INFO - Poking for /path/to/monitor, with pattern 
[2024-03-18T04:31:45.891+0000] {ssh.py:301} WARNING - No Host Key Verification. This won't protect against Man-In-The-Middle attacks
[2024-03-18T04:31:47.224+0000] {transport.py:1909} INFO - Connected (version 2.0, client OpenSSH_8.9p1)
[2024-03-18T04:31:50.615+0000] {transport.py:1909} INFO - Authentication (password) successful!
[2024-03-18T04:31:50.902+0000] {sftp.py:169} INFO - [chan 0] Opened sftp connection (server version 3)
[2024-03-18T04:31:50.911+0000] {sftp.py:169} INFO - [chan 0] sftp session closed.
[2024-03-18T04:32:31.404+0000] {base.py:83} INFO - Using connection ID 'source_sftp' for task execution.
[2024-03-18T04:32:31.533+0000] {sftp.py:80} INFO - Poking for /path/to/monitor, with pattern 
[2024-03-18T04:32:31.541+0000] {ssh.py:301} WARNING - No Host Key Verification. This won't protect against Man-In-The-Middle attacks
[2024-03-18T04:32:38.364+0000] {transport.py:1909} INFO - Connected (version 2.0, client OpenSSH_8.9p1)
[2024-03-18T04:32:42.151+0000] {ssh.py:343} INFO - Failed to connect. Sleeping before retry attempt 1
[2024-03-18T04:33:02.659+0000] {ssh.py:343} INFO - Failed to connect. Sleeping before retry attempt 2
[2024-03-18T04:32:57.057+0000] {job.py:213} ERROR - Job heartbeat got an exception
Traceback (most recent call last):
  File "/home/airflow/.local/lib/python3.8/site-packages/sqlalchemy/engine/base.py", line 3371, in _wrap_pool_connect
    return fn()
  File "/home/airflow/.local/lib/python3.8/site-packages/sqlalchemy/pool/base.py", line 327, in connect
    return _ConnectionFairy._checkout(self)
  File "/home/airflow/.local/lib/python3.8/site-packages/sqlalchemy/pool/base.py", line 894, in _checkout
    fairy = _ConnectionRecord.checkout(pool)
  File "/home/airflow/.local/lib/python3.8/site-packages/sqlalchemy/pool/base.py", line 493, in checkout
    rec = pool._do_get()
  File "/home/airflow/.local/lib/python3.8/site-packages/sqlalchemy/pool/impl.py", line 256, in _do_get
    return self._create_connection()
  File "/home/airflow/.local/lib/python3.8/site-packages/sqlalchemy/pool/base.py", line 273, in _create_connection
    return _ConnectionRecord(self)
  File "/home/airflow/.local/lib/python3.8/site-packages/sqlalchemy/pool/base.py", line 388, in __init__
    self.__connect()
  File "/home/airflow/.local/lib/python3.8/site-packages/sqlalchemy/pool/base.py", line 691, in __connect
    pool.logger.debug("Error on connect(): %s", e)
  File "/home/airflow/.local/lib/python3.8/site-packages/sqlalchemy/util/langhelpers.py", line 70, in __exit__
    compat.raise_(
  File "/home/airflow/.local/lib/python3.8/site-packages/sqlalchemy/util/compat.py", line 211, in raise_
    raise exception
  File "/home/airflow/.local/lib/python3.8/site-packages/sqlalchemy/pool/base.py", line 686, in __connect
    self.dbapi_connection = connection = pool._invoke_creator(self)
  File "/home/airflow/.local/lib/python3.8/site-packages/sqlalchemy/engine/create.py", line 574, in connect
    return dialect.connect(*cargs, **cparams)
  File "/home/airflow/.local/lib/python3.8/site-packages/sqlalchemy/engine/default.py", line 598, in connect
    return self.dbapi.connect(*cargs, **cparams)
  File "/home/airflow/.local/lib/python3.8/site-packages/psycopg2/__init__.py", line 122, in connect
    conn = _connect(dsn, connection_factory=connection_factory, **kwasync)
psycopg2.OperationalError: could not translate host name "postgres" to address: Temporary failure in name resolution


The above exception was the direct cause of the following exception:

Traceback (most recent call last):
  File "/home/airflow/.local/lib/python3.8/site-packages/airflow/jobs/job.py", line 187, in heartbeat
    self._merge_from(Job._fetch_from_db(self, session))
  File "/home/airflow/.local/lib/python3.8/site-packages/airflow/api_internal/internal_api_call.py", line 114, in wrapper
    return func(*args, **kwargs)
  File "/home/airflow/.local/lib/python3.8/site-packages/airflow/utils/session.py", line 76, in wrapper
    return func(*args, **kwargs)
  File "/home/airflow/.local/lib/python3.8/site-packages/airflow/jobs/job.py", line 308, in _fetch_from_db
    session.merge(job)
  File "/home/airflow/.local/lib/python3.8/site-packages/sqlalchemy/orm/session.py", line 3056, in merge
    return self._merge(
  File "/home/airflow/.local/lib/python3.8/site-packages/sqlalchemy/orm/session.py", line 3136, in _merge
    merged = self.get(
  File "/home/airflow/.local/lib/python3.8/site-packages/sqlalchemy/orm/session.py", line 2853, in get
    return self._get_impl(
  File "/home/airflow/.local/lib/python3.8/site-packages/sqlalchemy/orm/session.py", line 2975, in _get_impl
    return db_load_fn(
  File "/home/airflow/.local/lib/python3.8/site-packages/sqlalchemy/orm/loading.py", line 530, in load_on_pk_identity
    session.execute(
  File "/home/airflow/.local/lib/python3.8/site-packages/sqlalchemy/orm/session.py", line 1716, in execute
    conn = self._connection_for_bind(bind)
  File "/home/airflow/.local/lib/python3.8/site-packages/sqlalchemy/orm/session.py", line 1555, in _connection_for_bind
    return self._transaction._connection_for_bind(
  File "/home/airflow/.local/lib/python3.8/site-packages/sqlalchemy/orm/session.py", line 750, in _connection_for_bind
    conn = bind.connect()
  File "/home/airflow/.local/lib/python3.8/site-packages/sqlalchemy/future/engine.py", line 412, in connect
    return super(Engine, self).connect()
  File "/home/airflow/.local/lib/python3.8/site-packages/sqlalchemy/engine/base.py", line 3325, in connect
    return self._connection_cls(self, close_with_result=close_with_result)
  File "/home/airflow/.local/lib/python3.8/site-packages/sqlalchemy/engine/base.py", line 96, in __init__
    else engine.raw_connection()
  File "/home/airflow/.local/lib/python3.8/site-packages/sqlalchemy/engine/base.py", line 3404, in raw_connection
    return self._wrap_pool_connect(self.pool.connect, _connection)
  File "/home/airflow/.local/lib/python3.8/site-packages/sqlalchemy/engine/base.py", line 3374, in _wrap_pool_connect
    Connection._handle_dbapi_exception_noconnection(
  File "/home/airflow/.local/lib/python3.8/site-packages/sqlalchemy/engine/base.py", line 2208, in _handle_dbapi_exception_noconnection
    util.raise_(
  File "/home/airflow/.local/lib/python3.8/site-packages/sqlalchemy/util/compat.py", line 211, in raise_
    raise exception
  File "/home/airflow/.local/lib/python3.8/site-packages/sqlalchemy/engine/base.py", line 3371, in _wrap_pool_connect
    return fn()
  File "/home/airflow/.local/lib/python3.8/site-packages/sqlalchemy/pool/base.py", line 327, in connect
    return _ConnectionFairy._checkout(self)
  File "/home/airflow/.local/lib/python3.8/site-packages/sqlalchemy/pool/base.py", line 894, in _checkout
    fairy = _ConnectionRecord.checkout(pool)
  File "/home/airflow/.local/lib/python3.8/site-packages/sqlalchemy/pool/base.py", line 493, in checkout
    rec = pool._do_get()
  File "/home/airflow/.local/lib/python3.8/site-packages/sqlalchemy/pool/impl.py", line 256, in _do_get
    return self._create_connection()
  File "/home/airflow/.local/lib/python3.8/site-packages/sqlalchemy/pool/base.py", line 273, in _create_connection
    return _ConnectionRecord(self)
  File "/home/airflow/.local/lib/python3.8/site-packages/sqlalchemy/pool/base.py", line 388, in __init__
    self.__connect()
  File "/home/airflow/.local/lib/python3.8/site-packages/sqlalchemy/pool/base.py", line 691, in __connect
    pool.logger.debug("Error on connect(): %s", e)
  File "/home/airflow/.local/lib/python3.8/site-packages/sqlalchemy/util/langhelpers.py", line 70, in __exit__
    compat.raise_(
  File "/home/airflow/.local/lib/python3.8/site-packages/sqlalchemy/util/compat.py", line 211, in raise_
    raise exception
  File "/home/airflow/.local/lib/python3.8/site-packages/sqlalchemy/pool/base.py", line 686, in __connect
    self.dbapi_connection = connection = pool._invoke_creator(self)
  File "/home/airflow/.local/lib/python3.8/site-packages/sqlalchemy/engine/create.py", line 574, in connect
    return dialect.connect(*cargs, **cparams)
  File "/home/airflow/.local/lib/python3.8/site-packages/sqlalchemy/engine/default.py", line 598, in connect
    return self.dbapi.connect(*cargs, **cparams)
  File "/home/airflow/.local/lib/python3.8/site-packages/psycopg2/__init__.py", line 122, in connect
    conn = _connect(dsn, connection_factory=connection_factory, **kwasync)
sqlalchemy.exc.OperationalError: (psycopg2.OperationalError) could not translate host name "postgres" to address: Temporary failure in name resolution

(Background on this error at: https://sqlalche.me/e/14/e3q8)
[2024-03-18T04:33:05.650+0000] {job.py:221} ERROR - Job heartbeat failed with error. Scheduler is in unhealthy state
[2024-03-18T04:33:10.288+0000] {transport.py:1909} ERROR - Exception (client): Error reading SSH protocol banner[Errno 104] Connection reset by peer
[2024-03-18T04:33:11.194+0000] {transport.py:1907} ERROR - Traceback (most recent call last):
[2024-03-18T04:33:11.534+0000] {transport.py:1907} ERROR -   File "/home/***/.local/lib/python3.8/site-packages/paramiko/transport.py", line 2327, in _check_banner
[2024-03-18T04:33:11.996+0000] {transport.py:1907} ERROR -     buf = self.packetizer.readline(timeout)
[2024-03-18T04:33:12.416+0000] {transport.py:1907} ERROR -   File "/home/***/.local/lib/python3.8/site-packages/paramiko/packet.py", line 381, in readline
[2024-03-18T04:33:12.687+0000] {transport.py:1907} ERROR -     buf += self._read_timeout(timeout)
[2024-03-18T04:33:13.101+0000] {transport.py:1907} ERROR -   File "/home/***/.local/lib/python3.8/site-packages/paramiko/packet.py", line 616, in _read_timeout
[2024-03-18T04:33:13.860+0000] {transport.py:1907} ERROR -     x = self.__socket.recv(128)
[2024-03-18T04:33:14.484+0000] {transport.py:1907} ERROR - ConnectionResetError: [Errno 104] Connection reset by peer
[2024-03-18T04:33:15.385+0000] {transport.py:1907} ERROR - 
[2024-03-18T04:33:15.487+0000] {transport.py:1907} ERROR - During handling of the above exception, another exception occurred:
[2024-03-18T04:33:15.551+0000] {transport.py:1907} ERROR - 
[2024-03-18T04:33:15.952+0000] {transport.py:1907} ERROR - Traceback (most recent call last):
[2024-03-18T04:33:16.115+0000] {transport.py:1907} ERROR -   File "/home/***/.local/lib/python3.8/site-packages/paramiko/transport.py", line 2143, in run
[2024-03-18T04:33:17.249+0000] {transport.py:1907} ERROR -     self._check_banner()
[2024-03-18T04:33:18.186+0000] {transport.py:1907} ERROR -   File "/home/***/.local/lib/python3.8/site-packages/paramiko/transport.py", line 2331, in _check_banner
[2024-03-18T04:33:18.472+0000] {transport.py:1907} ERROR -     raise SSHException(
[2024-03-18T04:33:19.059+0000] {transport.py:1907} ERROR - paramiko.ssh_exception.SSHException: Error reading SSH protocol banner[Errno 104] Connection reset by peer
[2024-03-18T04:33:19.860+0000] {transport.py:1907} ERROR - 
[2024-03-18T04:33:21.649+0000] {job.py:221} ERROR - Job heartbeat failed with error. Scheduler is in unhealthy state
[2024-03-18T04:33:20.820+0000] {taskinstance.py:2731} ERROR - Task failed with exception
Traceback (most recent call last):
  File "/home/airflow/.local/lib/python3.8/site-packages/airflow/models/taskinstance.py", line 444, in _execute_task
    result = _execute_callable(context=context, **execute_callable_kwargs)
  File "/home/airflow/.local/lib/python3.8/site-packages/airflow/models/taskinstance.py", line 414, in _execute_callable
    return execute_callable(context=context, **execute_callable_kwargs)
  File "/home/airflow/.local/lib/python3.8/site-packages/airflow/providers/sftp/sensors/sftp.py", line 154, in execute
    return super().execute(context=context)
  File "/home/airflow/.local/lib/python3.8/site-packages/airflow/sensors/base.py", line 265, in execute
    raise e
  File "/home/airflow/.local/lib/python3.8/site-packages/airflow/sensors/base.py", line 247, in execute
    poke_return = self.poke(context)
  File "/home/airflow/.local/lib/python3.8/site-packages/airflow/providers/sftp/sensors/sftp.py", line 96, in poke
    mod_time = self.hook.get_mod_time(actual_file_to_check)
  File "/home/airflow/.local/lib/python3.8/site-packages/airflow/providers/sftp/hooks/sftp.py", line 271, in get_mod_time
    conn = self.get_conn()
  File "/home/airflow/.local/lib/python3.8/site-packages/airflow/providers/sftp/hooks/sftp.py", line 126, in get_conn
    self.conn = super().get_conn().open_sftp()
  File "/home/airflow/.local/lib/python3.8/site-packages/airflow/providers/ssh/hooks/ssh.py", line 347, in get_conn
    for attempt in Retrying(
  File "/home/airflow/.local/lib/python3.8/site-packages/tenacity/__init__.py", line 347, in __iter__
    do = self.iter(retry_state=retry_state)
  File "/home/airflow/.local/lib/python3.8/site-packages/tenacity/__init__.py", line 325, in iter
    raise retry_exc.reraise()
  File "/home/airflow/.local/lib/python3.8/site-packages/tenacity/__init__.py", line 158, in reraise
    raise self.last_attempt.result()
  File "/usr/local/lib/python3.8/concurrent/futures/_base.py", line 437, in result
    return self.__get_result()
  File "/usr/local/lib/python3.8/concurrent/futures/_base.py", line 389, in __get_result
    raise self._exception
  File "/home/airflow/.local/lib/python3.8/site-packages/airflow/providers/ssh/hooks/ssh.py", line 354, in get_conn
    client.connect(**connect_kwargs)
  File "/home/airflow/.local/lib/python3.8/site-packages/paramiko/client.py", line 457, in connect
    server_key = t.get_remote_server_key()
  File "/home/airflow/.local/lib/python3.8/site-packages/paramiko/transport.py", line 918, in get_remote_server_key
    raise SSHException("No existing session")
paramiko.ssh_exception.SSHException: No existing session
[2024-03-18T04:33:46.033+0000] {job.py:221} ERROR - Job heartbeat failed with error. Scheduler is in unhealthy state
[2024-03-18T04:33:48.188+0000] {standard_task_runner.py:107} ERROR - Failed to execute job 33 for task sftp_sensor_task ((psycopg2.OperationalError) could not translate host name "postgres" to address: Temporary failure in name resolution

(Background on this error at: https://sqlalche.me/e/14/e3q8); 302)
[2024-03-18T04:33:49.289+0000] {local_task_job_runner.py:234} INFO - Task exited with return code 1
[2024-03-18T04:33:55.197+0000] {taskinstance.py:3312} INFO - 0 downstream tasks scheduled from follow-on schedule check
